Workbook

Sheet Original_Data
A1: store_id | B1: month | C1: region | D1: store_type | E1: marketing_spend | F1: footfall | G1: avg_discount_pct | H1: staff_count | I1: inventory_availability_pct | J1: competitor_distance_km | K1: holiday_flag | L1: customer_rating | M1: monthly_sales | N1: monthly_profit
A2: STR-1001 | B2: 45658 | C2: East | D2: Residential | E2: 70389.11 | F2: 8302 | G2: 0.042 | H2: 17 | I2: 75 | J2: 5.28 | K2: 1 | L2: 3.1 | M2: 658832.62 | N2: 84349.93
A3: STR-1001 | B3: 45689 | C3: East | D3: Residential | E3: 43827.89 | F3: 8487 | G3: 0.168 | H3: 23 | I3: 84.4 | J3: 4.31 | K3: 0 | L3: 2.8 | M3: 634436 | N3: 106130.54
A4: STR-1001 | B4: 45717 | C4: East | D4: Residential | E4: 59921.75 | F4: 9113 | G4: 0.133 | H4: 20 | I4: 88 | J4: 12 | K4: 0 | L4: 3.2 | M4: 678722.06 | N4: 101883.86
A5: STR-1001 | B5: 45748 | C5: East | D5: Residential | E5: 56856.63 | F5: 9431 | G5: 0.142 | H5: 23 | I5: 86.9 | J5: 4.97 | K5: 0 | L5: 3.4 | M5: 658920.3 | N5: 97910.37
A6: STR-1002 | B6: 45658 | C6: East | D6: High Street | E6: 48412.64 | F6: 9545 | G6: 0.231 | H6: 21 | I6: 97.6 | J6: 6.94 | K6: 1 | L6: 4.2 | M6: 741341.44 | N6: 119208.17
A7: STR-1002 | B7: 45689 | C7: East | D7: High Street | E7: 64811.21 | F7: 9792 | G7: 0.112 | H7: 20 | I7: 84.2 | J7: 2.88 | K7: 0 | L7: 4.2 | M7: 761835.34 | N7: 149602.23
A8: STR-1002 | B8: 45717 | C8: East | D8: High Street | E8: 46213.45 | F8: 10616 | G8: 0.122 | H8: 22 | I8: 85.2 | J8: 0.2 | K8: 1 | L8: 4.1 | M8: 806615.54 | N8: 131364.62
A9: STR-1002 | B9: 45748 | C9: East | D9: High Street | E9: 68148.52 | F9: 8567 | G9: 0.127 | H9: 23 | I9: 95.6 | J9: 0.8 | K9: 0 | L9: 3.9 | M9: 850164.26 | N9: 149262.75
A10: STR-1003 | B10: 45658 | C10: North | D10: Airport | E10: 71838.86 | F10: 10979 | G10: 0.215 | H10: 26 | I10: 88.6 | J10: 7.7 | K10: 1 | L10: 3.8 | M10: 930581.7 | N10: 136207.98
A11: STR-1003 | B11: 45689 | C11: North | D11: Airport | E11: 68133.44 | F11: 9459 | G11: 0.22 | H11: 21 | I11: 85 | J11: 1.91 | K11: 0 | L11: 4.2 | M11: 779010.94 | N11: 106328.09
A12: STR-1003 | B12: 45717 | C12: North | D12: Airport | E12: 34285.21 | F12: 9172 | G12: 0.213 | H12: 22 | I12: 88.3 | J12: 10.46 | K12: 1 | L12: 3.8 | M12: 723060.76 | N12: 123131.24
A13: STR-1003 | B13: 45748 | C13: North | D13: Airport | E13: 67979.88 | F13: 11230 | G13: 0.002 | H13: 28 | I13: 85.3 | J13: 7.16 | K13: 0 | L13: 3.8 | M13: 910791.94 | N13: 158891.28
... A34: STR-1009 | B34: 45658 | C34: North | D34: Residential | E34: 54597.83 | F34: 9429 | G34: 0.188 | H34: 21 | I34: 83.3 | J34: 11.71 | K34: 0 | L34: 4.2 | M34: 641865.03 | N34: 81342.58
A35: STR-1009 | B35: 45689 | C35: North | D35: Residential | E35: 73771.91 | F35: 11695 | G35: 0.07 | H35: 25 | I35: 84.7 | J35: 0.62 | K35: 0 | M35: 799477.76 | N35: 164974.41
A36: STR-1009 | B36: 45717 | C36: North | D36: Residential | E36: 74413.88 | F36: 9449 | G36: 0.039 | H36: 23 | I36: 92.1 | J36: 2.12 | K36: 0 | L36: 3.5 | M36: 798952.17 | N36: 161499.04
A37: STR-1009 | B37: 45748 | C37: North | D37: Residential | E37: 52483.77 | F37: 10453 | G37: 0.247 | H37: 25 | I37: 99 | J37: 6.31 | K37: 0 | L37: 3.6 | M37: 800979.78 | N37: 149242.27
A38: STR-1010 | B38: 45658 | C38: North | D38: Mall | E38: 75269.87 | F38: 8838 | G38: 0.092 | H38: 21 | I38: 83.1 | J38: 9.56 | K38: 1 | L38: 4.2 | M38: 820593.93 | N38: 115860.06
A39: STR-1010 | B39: 45689 | C39: North | D39: Mall | E39: 61245.41 | F39: 8156 | G39: 0.156 | H39: 19 | I39: 92.9 | J39: 9.05 | K39: 0 | L39: 3.8 | M39: 718330.53 | N39: 93247.9
A40: STR-1010 | B40: 45717 | C40: North | D40: Mall | E40: 93381.26 | F40: 7562 | G40: 0.198 | H40: 19 | I40: 82.9 | J40: 5.05 | K40: 0 | L40: 4 | M40: 736633.4 | N40: 115654.66
A41: STR-1010 | B41: 45748 | C41: North | D41: Mall | E41: 65012.19 | F41: 9598 | G41: 0.085 | H41: 24 | I41: 98.3 | J41: 0.89 | K41: 0 | L41: 3.8 | M41: 828623.85 | N41: 167320.52
A42: STR-1011 | B42: 45658 | C42: East | D42: Mall | E42: 40462.94 | F42: 3660 | G42: 0.218 | H42: 11 | I42: 95.2 | J42: 5.57 | K42: 0 | L42: 4.4 | M42: 592195.85 | N42: 92291.56
A43: STR-1011 | B43: 45689 | C43: East | D43: Mall | E43: 46123.88 | F43: 3227 | G43: 0.143 | H43: 10 | I43: 75.4 | J43: 1.06 | K43: 0 | L43: 4.4 | M43: 532644.46 | N43: 60681.32
A44: STR-1011 | B44: 45717 | C44: East | D44: Mall | E44: 68077.54 | F44: 3360 | G44: 0.128 | H44: 14 | I44: 88.2 | J44: 1.24 | K44: 1 | L44: 4 | M44: 657429.18 | N44: 88919.74
A45: STR-1011 | B45: 45748 | C45: East | D45: Mall | E45: 64882.14 | F45: 3642 | G45: 0.019 | H45: 13 | I45: 87.8 | J45: 4.52 | K45: 0 | L45: 4.2 | M45: 605178 | N45: 106958.74
A46: STR-1012 | B46: 45658 | C46: West | D46: Residential | E46: 138855.51 | F46: 5145 | G46: 0.06 | H46: 17 | I46: 88.2 | J46: 9.58 | K46: 0 | L46: 3.2 | M46: 595467.6 | N46: 104276.46
A47: STR-1012 | B47: 45689 | C47: West | D47: Residential | E47: 63630.21 | F47: 4460 | G47: 0.235 | H47: 14 | I47: 98.6 | J47: 5.52 | K47: 0 | L47: 3.5 | M47: 599603.4 | N47: 112685.12
... A72: STR-1018 | B72: 45717 | C72: East | D72: High Street | E72: 60571.82 | F72: 3193 | G72: 0.197 | H72: 7 | I72: 99 | J72: 1.43 | K72: 0 | L72: 3.2 | M72: 605023.87 | N72: 98545.81
A73: STR-1018 | B73: 45748 | C73: East | D73: High Street | E73: 55081.16 | F73: 5485 | G73: 0.036 | H73: 12 | I73: 88 | K73: 0 | L73: 3.5 | M73: 674774.09 | N73: 141917.59
A74: STR-1019 | B74: 45658 | C74: East | D74: Residential | E74: 46201.46 | F74: 5918 | G74: 0.277 | H74: 13 | I74: 78.8 | J74: 4.91 | K74: 0 | L74: 4.5 | M74: 616069.41 | N74: 54453.99
A75: STR-1019 | B75: 45689 | C75: East | D75: Residential | E75: 53762.92 | F75: 6821 | G75: 0.066 | H75: 19 | I75: 94.6 | J75: 7.03 | K75: 0 | L75: 4.4 | M75: 630829.94 | N75: 117090.02
A76: STR-1019 | B76: 45717 | C76: East | D76: Residential | E76: 70144.78 | F76: 6806 | G76: 0.178 | H76: 20 | I76: 93.1 | J76: 0.28 | K76: 1 | L76: 4.3 | M76: 788087.68 | N76: 116803.42
A77: STR-1019 | B77: 45748 | C77: East | D77: Residential | E77: 58749.63 | F77: 8252 | G77: 0.203 | H77: 20 | I77: 85.2 | J77: 3.61 | K77: 0 | L77: 4.5 | M77: 680840.36 | N77: 68007.68
A78: STR-1020 | B78: 45658 | C78: South | D78: High Street | E78: 56973.18 | F78: 6662 | G78: 0.1 | H78: 15 | I78: 77.7 | J78: 7.52 | K78: 1 | L78: 3.2 | M78: 643657.47 | N78: 87022.45
A79: STR-1020 | B79: 45689 | C79: South | D79: High Street | E79: 54872.82 | F79: 5962 | G79: 0.064 | H79: 12 | I79: 85.4 | J79: 2.58 | K79: 0 | L79: 2.9 | M79: 691112.6 | N79: 109212.83
A80: STR-1020 | B80: 45717 | C80: South | D80: High Street | E80: 80562.81 | F80: 7470 | G80: 0.172 | H80: 16 | I80: 83.5 | J80: 2.29 | K80: 0 | L80: 3.3 | M80: 776922.17 | N80: 150701.93
A81: STR-1020 | B81: 45748 | C81: South | D81: High Street | E81: 77999.9 | F81: 5974 | G81: 0.252 | H81: 14 | I81: 81.3 | J81: 2.39 | K81: 0 | L81: 3.2 | M81: 636561.34 | N81: 93861.06
A82: STR-1021 | B82: 45658 | C82: West | D82: Mall | E82: 60881.01 | F82: 5410 | G82: 0.179 | H82: 15 | I82: 83.9 | J82: 5.24 | K82: 0 | L82: 4.6 | M82: 621369.58 | N82: 85493.64
A83: STR-1021 | B83: 45689 | C83: West | D83: Mall | E83: 60628.38 | F83: 4451 | G83: 0.095 | H83: 10 | I83: 89.6 | J83: 3.17 | K83: 0 | L83: 4.6 | M83: 682208.01 | N83: 110318.84
A84: STR-1021 | B84: 45717 | C84: West | D84: Mall | E84: 72731.14 | F84: 4644 | G84: 0.084 | H84: 15 | I84: 87.1 | J84: 2.66 | K84: 0 | L84: 4.6 | M84: 727241.86 | N84: 155810.3
...

Sheet Cleaned_Data
A1: store_id | B1: month | C1: region | D1: store_type | E1: marketing_spend | F1: footfall | G1: avg_discount_pct | H1: staff_count | I1: inventory_availability_pct | J1: competitor_distance_km | K1: holiday_flag | L1: customer_rating | M1: monthly_sales | N1: monthly_profit | O1: missing_flag
A2: Rows with missing customer_rating or competitor_distance_km are excluded. Cleaned rows: 306 of 320.
A3: STR-1001 | B3: 45658 | C3: East | D3: Residential | E3: 70389.11 | F3: 8302 | G3: 0.042 | H3: 17 | I3: 75 | J3: 5.28 | K3: 1 | L3: 3.1 | M3: 658832.62 | N3: 84349.93 | O3: =IF(AND(ISNUMBER(L3),ISNUMBER(J3)),0,1)
A4: STR-1001 | B4: 45689 | C4: East | D4: Residential | E4: 43827.89 | F4: 8487 | G4: 0.168 | H4: 23 | I4: 84.4 | J4: 4.31 | K4: 0 | L4: 2.8 | M4: 634436 | N4: 106130.54 | O4: =IF(AND(ISNUMBER(L4),ISNUMBER(J4)),0,1)
A5: STR-1001 | B5: 45717 | C5: East | D5: Residential | E5: 59921.75 | F5: 9113 | G5: 0.133 | H5: 20 | I5: 88 | J5: 12 | K5: 0 | L5: 3.2 | M5: 678722.06 | N5: 101883.86 | O5: =IF(AND(ISNUMBER(L5),ISNUMBER(J5)),0,1)
A6: STR-1001 | B6: 45748 | C6: East | D6: Residential | E6: 56856.63 | F6: 9431 | G6: 0.142 | H6: 23 | I6: 86.9 | J6: 4.97 | K6: 0 | L6: 3.4 | M6: 658920.3 | N6: 97910.37 | O6: =IF(AND(ISNUMBER(L6),ISNUMBER(J6)),0,1)
A7: STR-1002 | B7: 45658 | C7: East | D7: High Street | E7: 48412.64 | F7: 9545 | G7: 0.231 | H7: 21 | I7: 97.6 | J7: 6.94 | K7: 1 | L7: 4.2 | M7: 741341.44 | N7: 119208.17 | O7: =IF(AND(ISNUMBER(L7),ISNUMBER(J7)),0,1)
A8: STR-1002 | B8: 45689 | C8: East | D8: High Street | E8: 64811.21 | F8: 9792 | G8: 0.112 | H8: 20 | I8: 84.2 | J8: 2.88 | K8: 0 | L8: 4.2 | M8: 761835.34 | N8: 149602.23 | O8: =IF(AND(ISNUMBER(L8),ISNUMBER(J8)),0,1)
A9: STR-1002 | B9: 45717 | C9: East | D9: High Street | E9: 46213.45 | F9: 10616 | G9: 0.122 | H9: 22 | I9: 85.2 | J9: 0.2 | K9: 1 | L9: 4.1 | M9: 806615.54 | N9: 131364.62 | O9: =IF(AND(ISNUMBER(L9),ISNUMBER(J9)),0,1)
A10: STR-1002 | B10: 45748 | C10: East | D10: High Street | E10: 68148.52 | F10: 8567 | G10: 0.127 | H10: 23 | I10: 95.6 | J10: 0.8 | K10: 0 | L10: 3.9 | M10: 850164.26 | N10: 149262.75 | O10: =IF(AND(ISNUMBER(L10),ISNUMBER(J10)),0,1)
A11: STR-1003 | B11: 45658 | C11: North | D11: Airport | E11: 71838.86 | F11: 10979 | G11: 0.215 | H11: 26 | I11: 88.6 | J11: 7.7 | K11: 1 | L11: 3.8 | M11: 930581.7 | N11: 136207.98 | O11: =IF(AND(ISNUMBER(L11),ISNUMBER(J11)),0,1)
A12: STR-1003 | B12: 45689 | C12: North | D12: Airport | E12: 68133.44 | F12: 9459 | G12: 0.22 | H12: 21 | I12: 85 | J12: 1.91 | K12: 0 | L12: 4.2 | M12: 779010.94 | N12: 106328.09 | O12: =IF(AND(ISNUMBER(L12),ISNUMBER(J12)),0,1)
A13: STR-1003 | B13: 45717 | C13: North | D13: Airport | E13: 34285.21 | F13: 9172 | G13: 0.213 | H13: 22 | I13: 88.3 | J13: 10.46 | K13: 1 | L13: 3.8 | M13: 723060.76 | N13: 123131.24 | O13: =IF(AND(ISNUMBER(L13),ISNUMBER(J13)),0,1)
A14: STR-1003 | B14: 45748 | C14: North | D14: Airport | E14: 67979.88 | F14: 11230 | G14: 0.002 | H14: 28 | I14: 85.3 | J14: 7.16 | K14: 0 | L14: 3.8 | M14: 910791.94 | N14: 158891.28 | O14: =IF(AND(ISNUMBER(L14),ISNUMBER(J14)),0,1)
... A308: STR-1080 | B308: 45748 | C308: East | D308: Residential | E308: 40553.11 | F308: 5317 | G308: 0.165 | H308: 17 | I308: 84.3 | J308: 11.82 | K308: 0 | L308: 4.1 | M308: 559660.84 | N308: 71443.61 | O308: =IF(AND(ISNUMBER(L308),ISNUMBER(J308)),0,1)

Sheet Dummy_Variables
A1: store_id | B1: month | C1: region | D1: store_type | E1: is_high_street | F1: is_airport | G1: is_mall | H1: is_north | I1: is_south | J1: is_west
A2: Dummy variables created using IF formulas. Reference: store_type=Residential | region=East
A3: STR-1001 | B3: 45658 | C3: East | D3: Residential | E3: =IF(D3="High Street",1,0) | F3: =IF(D3="Airport",1,0) | G3: =IF(D3="Mall",1,0) | H3: =IF(C3="North",1,0) | I3: =IF(C3="South",1,0) | J3: =IF(C3="West",1,0)
A4: STR-1001 | B4: 45689 | C4: East | D4: Residential | E4: =IF(D4="High Street",1,0) | F4: =IF(D4="Airport",1,0) | G4: =IF(D4="Mall",1,0) | H4: =IF(C4="North",1,0) | I4: =IF(C4="South",1,0) | J4: =IF(C4="West",1,0)
A5: STR-1001 | B5: 45717 | C5: East | D5: Residential | E5: =IF(D5="High Street",1,0) | F5: =IF(D5="Airport",1,0) | G5: =IF(D5="Mall",1,0) | H5: =IF(C5="North",1,0) | I5: =IF(C5="South",1,0) | J5: =IF(C5="West",1,0)
A6: STR-1001 | B6: 45748 | C6: East | D6: Residential | E6: =IF(D6="High Street",1,0) | F6: =IF(D6="Airport",1,0) | G6: =IF(D6="Mall",1,0) | H6: =IF(C6="North",1,0) | I6: =IF(C6="South",1,0) | J6: =IF(C6="West",1,0)
A7: STR-1002 | B7: 45658 | C7: East | D7: High Street | E7: =IF(D7="High Street",1,0) | F7: =IF(D7="Airport",1,0) | G7: =IF(D7="Mall",1,0) | H7: =IF(C7="North",1,0) | I7: =IF(C7="South",1,0) | J7: =IF(C7="West",1,0)
A8: STR-1002 | B8: 45689 | C8: East | D8: High Street | E8: =IF(D8="High Street",1,0) | F8: =IF(D8="Airport",1,0) | G8: =IF(D8="Mall",1,0) | H8: =IF(C8="North",1,0) | I8: =IF(C8="South",1,0) | J8: =IF(C8="West",1,0)
A9: STR-1002 | B9: 45717 | C9: East | D9: High Street | E9: =IF(D9="High Street",1,0) | F9: =IF(D9="Airport",1,0) | G9: =IF(D9="Mall",1,0) | H9: =IF(C9="North",1,0) | I9: =IF(C9="South",1,0) | J9: =IF(C9="West",1,0)
A10: STR-1002 | B10: 45748 | C10: East | D10: High Street | E10: =IF(D10="High Street",1,0) | F10: =IF(D10="Airport",1,0) | G10: =IF(D10="Mall",1,0) | H10: =IF(C10="North",1,0) | I10: =IF(C10="South",1,0) | J10: =IF(C10="West",1,0)
A11: STR-1003 | B11: 45658 | C11: North | D11: Airport | E11: =IF(D11="High Street",1,0) | F11: =IF(D11="Airport",1,0) | G11: =IF(D11="Mall",1,0) | H11: =IF(C11="North",1,0) | I11: =IF(C11="South",1,0) | J11: =IF(C11="West",1,0)
A12: STR-1003 | B12: 45689 | C12: North | D12: Airport | E12: =IF(D12="High Street",1,0) | F12: =IF(D12="Airport",1,0) | G12: =IF(D12="Mall",1,0) | H12: =IF(C12="North",1,0) | I12: =IF(C12="South",1,0) | J12: =IF(C12="West",1,0)
A13: STR-1003 | B13: 45717 | C13: North | D13: Airport | E13: =IF(D13="High Street",1,0) | F13: =IF(D13="Airport",1,0) | G13: =IF(D13="Mall",1,0) | H13: =IF(C13="North",1,0) | I13: =IF(C13="South",1,0) | J13: =IF(C13="West",1,0)
A14: STR-1003 | B14: 45748 | C14: North | D14: Airport | E14: =IF(D14="High Street",1,0) | F14: =IF(D14="Airport",1,0) | G14: =IF(D14="Mall",1,0) | H14: =IF(C14="North",1,0) | I14: =IF(C14="South",1,0) | J14: =IF(C14="West",1,0)
... A308: STR-1080 | B308: 45748 | C308: East | D308: Residential | E308: =IF(D308="High Street",1,0) | F308: =IF(D308="Airport",1,0) | G308: =IF(D308="Mall",1,0) | H308: =IF(C308="North",1,0) | I308: =IF(C308="South",1,0) | J308: =IF(C308="West",1,0)

Sheet Simple_Regression_1
A1: Model 1: Simple Linear Regression — footfall → monthly_sales
A2: LINEST Array Output (select B3:C7, enter formula, press Ctrl+Shift+Enter)
A3: Statistic | B3: footfall (X) | C3: Intercept
A4: Coefficient (Row 1) | B4: =INDEX(LINEST(Cleaned_Data!$M$3:$M$308,Cleaned_Data!$F$3:$F$308,TRUE,TRUE),1,1) | C4: =INDEX(LINEST(Cleaned_Data!$M$3:$M$308,Cleaned_Data!$F$3:$F$308,TRUE,TRUE),1,2)
A5: Standard Error (Row 2) | B5: =INDEX(LINEST(Cleaned_Data!$M$3:$M$308,Cleaned_Data!$F$3:$F$308,TRUE,TRUE),2,1) | C5: =INDEX(LINEST(Cleaned_Data!$M$3:$M$308,Cleaned_Data!$F$3:$F$308,TRUE,TRUE),2,2)
A6: R² / SE of Y (Row 3) | B6: =INDEX(LINEST(Cleaned_Data!$M$3:$M$308,Cleaned_Data!$F$3:$F$308,TRUE,TRUE),3,1) | C6: =INDEX(LINEST(Cleaned_Data!$M$3:$M$308,Cleaned_Data!$F$3:$F$308,TRUE,TRUE),3,2)
A7: F-statistic / df_resid (Row 4) | B7: =INDEX(LINEST(Cleaned_Data!$M$3:$M$308,Cleaned_Data!$F$3:$F$308,TRUE,TRUE),4,1) | C7: =INDEX(LINEST(Cleaned_Data!$M$3:$M$308,Cleaned_Data!$F$3:$F$308,TRUE,TRUE),4,2)
A8: SS_reg / SS_resid (Row 5) | B8: =INDEX(LINEST(Cleaned_Data!$M$3:$M$308,Cleaned_Data!$F$3:$F$308,TRUE,TRUE),5,1) | C8: =INDEX(LINEST(Cleaned_Data!$M$3:$M$308,Cleaned_Data!$F$3:$F$308,TRUE,TRUE),5,2)
A10: Regression Summary Table
A11: Variable | B11: Coefficient | C11: Std Error | D11: t-Statistic | E11: P-value | F11: Significant?
B12: Intercept | C12: =INDEX(LINEST(Cleaned_Data!$M$3:$M$308,Cleaned_Data!$F$3:$F$308,TRUE,TRUE),1,2) | D12: =INDEX(LINEST(Cleaned_Data!$M$3:$M$308,Cleaned_Data!$F$3:$F$308,TRUE,TRUE),2,2) | E12: =INDEX(LINEST(Cleaned_Data!$M$3:$M$308,Cleaned_Data!$F$3:$F$308,TRUE,TRUE),1,2)/INDEX(LINEST(Cleaned_Data!$M$3:$M$308,Cleaned_Data!$F$3:$F$308,TRUE,TRUE),2,2) | F12: =2*(1-T.DIST(ABS(D12),306-2,TRUE)) | G12: =IF(E12<0.05,"Yes ✓","No ✗")
B13: footfall | C13: =INDEX(LINEST(Cleaned_Data!$M$3:$M$308,Cleaned_Data!$F$3:$F$308,TRUE,TRUE),1,1) | D13: =INDEX(LINEST(Cleaned_Data!$M$3:$M$308,Cleaned_Data!$F$3:$F$308,TRUE,TRUE),2,1) | E13: =INDEX(LINEST(Cleaned_Data!$M$3:$M$308,Cleaned_Data!$F$3:$F$308,TRUE,TRUE),1,1)/INDEX(LINEST(Cleaned_Data!$M$3:$M$308,Cleaned_Data!$F$3:$F$308,TRUE,TRUE),2,1) | F13: =2*(1-T.DIST(ABS(D13),306-2,TRUE)) | G13: =IF(E13<0.05,"Yes ✓","No ✗")
A15: Model Statistics
A16: R-squared (R²) | B16: =INDEX(LINEST(Cleaned_Data!$M$3:$M$308,Cleaned_Data!$F$3:$F$308,TRUE,TRUE),3,1)
A17: Observations (n) | B17: =COUNTA(Cleaned_Data!$M$3:$M$308)
A18: Degrees of Freedom | B18: =COUNTA(Cleaned_Data!$M$3:$M$308)-2
A19: F-statistic | B19: =INDEX(LINEST(Cleaned_Data!$M$3:$M$308,Cleaned_Data!$F$3:$F$308,TRUE,TRUE),4,1)
A20: F p-value | B20: =F.DIST.RT(B19,1,306-2)
A21: Regression Equation | B21: ="monthly_sales = "&TEXT(INDEX(LINEST(Cleaned_Data!$M$3:$M$308,Cleaned_Data!$F$3:$F$308,TRUE,TRUE),1,2),"0.00")&" + "&TEXT(INDEX(LINEST(Cleaned_Data!$M$3:$M$308,Cleaned_Data!$F$3:$F$308,TRUE,TRUE),1,1),"0.0000")&" × footfall"
A23: Business Interpretation
A24: Each additional customer visit is associated with £35.64 in additional monthly sales.
A25: Footfall alone explains 73.5% of variation in monthly_sales — the strongest single predictor.
A26: P-value < 0.001 confirms the relationship is highly statistically significant.
A27: Business Action: Leadership should prioritise footfall-driving initiatives (events, loyalty, location).

Sheet Simple_Regression_2
A1: Model 2: Simple Linear Regression — marketing_spend → monthly_sales
A2: LINEST Array Output — marketing_spend
A3: Statistic | B3: marketing_spend (X) | C3: Intercept
A4: Coefficient (Row 1) | B4: =INDEX(LINEST(Cleaned_Data!$M$3:$M$308,Cleaned_Data!$E$3:$E$308,TRUE,TRUE),1,1) | C4: =INDEX(LINEST(Cleaned_Data!$M$3:$M$308,Cleaned_Data!$E$3:$E$308,TRUE,TRUE),1,2)
A5: Standard Error (Row 2) | B5: =INDEX(LINEST(Cleaned_Data!$M$3:$M$308,Cleaned_Data!$E$3:$E$308,TRUE,TRUE),2,1) | C5: =INDEX(LINEST(Cleaned_Data!$M$3:$M$308,Cleaned_Data!$E$3:$E$308,TRUE,TRUE),2,2)
A6: R² / SE of Y (Row 3) | B6: =INDEX(LINEST(Cleaned_Data!$M$3:$M$308,Cleaned_Data!$E$3:$E$308,TRUE,TRUE),3,1) | C6: =INDEX(LINEST(Cleaned_Data!$M$3:$M$308,Cleaned_Data!$E$3:$E$308,TRUE,TRUE),3,2)
A7: F-statistic / df_resid (Row 4) | B7: =INDEX(LINEST(Cleaned_Data!$M$3:$M$308,Cleaned_Data!$E$3:$E$308,TRUE,TRUE),4,1) | C7: =INDEX(LINEST(Cleaned_Data!$M$3:$M$308,Cleaned_Data!$E$3:$E$308,TRUE,TRUE),4,2)
A8: SS_reg / SS_resid (Row 5) | B8: =INDEX(LINEST(Cleaned_Data!$M$3:$M$308,Cleaned_Data!$E$3:$E$308,TRUE,TRUE),5,1) | C8: =INDEX(LINEST(Cleaned_Data!$M$3:$M$308,Cleaned_Data!$E$3:$E$308,TRUE,TRUE),5,2)
A10: Regression Summary Table
A11: Variable | B11: Coefficient | C11: Std Error | D11: t-Statistic | E11: P-value | F11: Significant?
A12: Intercept | B12: =INDEX(LINEST(Cleaned_Data!$M$3:$M$308,Cleaned_Data!$E$3:$E$308,TRUE,TRUE),1,2) | C12: =INDEX(LINEST(Cleaned_Data!$M$3:$M$308,Cleaned_Data!$E$3:$E$308,TRUE,TRUE),2,2) | D12: =B12/C12 | E12: =2*(1-T.DIST(ABS(D12),306-2,TRUE)) | F12: =IF(E12<0.05,"Yes ✓","No ✗")
A13: marketing_spend | B13: =INDEX(LINEST(Cleaned_Data!$M$3:$M$308,Cleaned_Data!$E$3:$E$308,TRUE,TRUE),1,1) | C13: =INDEX(LINEST(Cleaned_Data!$M$3:$M$308,Cleaned_Data!$E$3:$E$308,TRUE,TRUE),2,1) | D13: =B13/C13 | E13: =2*(1-T.DIST(ABS(D13),306-2,TRUE)) | F13: =IF(E13<0.05,"Yes ✓","No ✗")
A15: Model Statistics
A16: R-squared (R²) | B16: =INDEX(LINEST(Cleaned_Data!$M$3:$M$308,Cleaned_Data!$E$3:$E$308,TRUE,TRUE),3,1)
A17: Observations (n) | B17: =COUNTA(Cleaned_Data!$M$3:$M$308)
A18: Degrees of Freedom | B18: =COUNTA(Cleaned_Data!$M$3:$M$308)-2
A19: F-statistic | B19: =INDEX(LINEST(Cleaned_Data!$M$3:$M$308,Cleaned_Data!$E$3:$E$308,TRUE,TRUE),4,1)
A20: F p-value | B20: =F.DIST.RT(B19,1,306-2)
A21: Regression Equation | B21: ="monthly_sales = "&TEXT(INDEX(LINEST(Cleaned_Data!$M$3:$M$308,Cleaned_Data!$E$3:$E$308,TRUE,TRUE),1,2),"0.00")&" + "&TEXT(INDEX(LINEST(Cleaned_Data!$M$3:$M$308,Cleaned_Data!$E$3:$E$308,TRUE,TRUE),1,1),"0.000000")&" × marketing_spend"
A23: Business Interpretation
A24: Every £1 increase in marketing spend is associated with £2.05 more in monthly sales.
A25: However, marketing alone explains only 15.7% of sales variance — it is NOT the primary driver.
A26: P-value < 0.001 confirms significance, but low R² limits standalone usefulness.
A27: Caution: Some of this effect may reflect reverse causation (high-sales stores spend more on marketing).

Sheet Multiple_Regression
A1: Model 3: Multiple Linear Regression (Final Model) — 9 Predictors → monthly_sales
A2: Coefficient Table — t-statistics and p-values computed via Excel formulas
A3: Variable | B3: Coefficient | C3: Std Error | D3: t-Statistic (=B/C) | E3: P-value (T.DIST) | F3: Sig at 5%? | G3: Direction | H3: Business Interpretation
A4: Intercept | B4: 73762.675 | C4: 50049.773 | D4: =B4/C4 | E4: =2*(1-T.DIST(ABS(D4),306-10,TRUE)) | F4: =IF(E4<0.001,"★★★ p<0.001",IF(E4<0.01,"★★ p<0.01",IF(E4<0.05,"★ p<0.05",IF(E4<0.1,"~ Marginal","✗ NS")))) | G4: N/A | H4: Theoretical baseline — not meaningful alone
A5: footfall | B5: 33.5066 | C5: 1.0672 | D5: =B5/C5 | E5: =2*(1-T.DIST(ABS(D5),306-10,TRUE)) | F5: =IF(E5<0.001,"★★★ p<0.001",IF(E5<0.01,"★★ p<0.01",IF(E5<0.05,"★ p<0.05",IF(E5<0.1,"~ Marginal","✗ NS")))) | G5: Positive | H5: Each +1 visitor → +£33.51 monthly sales
A6: marketing_spend | B6: 1.174 | C6: 0.1305 | D6: =B6/C6 | E6: =2*(1-T.DIST(ABS(D6),306-10,TRUE)) | F6: =IF(E6<0.001,"★★★ p<0.001",IF(E6<0.01,"★★ p<0.01",IF(E6<0.05,"★ p<0.05",IF(E6<0.1,"~ Marginal","✗ NS")))) | G6: Positive | H6: Each +£1 marketing → +£1.17 monthly sales
A7: inventory_availability_pct | B7: 2954.4359 | C7: 482.7623 | D7: =B7/C7 | E7: =2*(1-T.DIST(ABS(D7),306-10,TRUE)) | F7: =IF(E7<0.001,"★★★ p<0.001",IF(E7<0.01,"★★ p<0.01",IF(E7<0.05,"★ p<0.05",IF(E7<0.1,"~ Marginal","✗ NS")))) | G7: Positive | H7: Each +1pp stock → +£2,954 monthly sales
A8: customer_rating | B8: 12808.63 | C8: 4855.9138 | D8: =B8/C8 | E8: =2*(1-T.DIST(ABS(D8),306-10,TRUE)) | F8: =IF(E8<0.001,"★★★ p<0.001",IF(E8<0.01,"★★ p<0.01",IF(E8<0.05,"★ p<0.05",IF(E8<0.1,"~ Marginal","✗ NS")))) | G8: Positive | H8: Each +1 rating point → +£12,809 monthly sales
A9: avg_discount_pct | B9: -57469.085 | C9: 37396.942 | D9: =B9/C9 | E9: =2*(1-T.DIST(ABS(D9),306-10,TRUE)) | F9: =IF(E9<0.001,"★★★ p<0.001",IF(E9<0.01,"★★ p<0.01",IF(E9<0.05,"★ p<0.05",IF(E9<0.1,"~ Marginal","✗ NS")))) | G9: Negative | H9: Higher discount associated with lower sales (not significant)
A10: holiday_flag | B10: 11148.515 | C10: 6720.1885 | D10: =B10/C10 | E10: =2*(1-T.DIST(ABS(D10),306-10,TRUE)) | F10: =IF(E10<0.001,"★★★ p<0.001",IF(E10<0.01,"★★ p<0.01",IF(E10<0.05,"★ p<0.05",IF(E10<0.1,"~ Marginal","✗ NS")))) | G10: Positive | H10: Holiday months add ~£11,149 (marginal significance)
A11: is_high_street | B11: 16295.025 | C11: 6235.5923 | D11: =B11/C11 | E11: =2*(1-T.DIST(ABS(D11),306-10,TRUE)) | F11: =IF(E11<0.001,"★★★ p<0.001",IF(E11<0.01,"★★ p<0.01",IF(E11<0.05,"★ p<0.05",IF(E11<0.1,"~ Marginal","✗ NS")))) | G11: Positive | H11: High Street earns +£16,295 vs Residential (reference)
A12: is_airport | B12: 38824.963 | C12: 9562.45 | D12: =B12/C12 | E12: =2*(1-T.DIST(ABS(D12),306-10,TRUE)) | F12: =IF(E12<0.001,"★★★ p<0.001",IF(E12<0.01,"★★ p<0.01",IF(E12<0.05,"★ p<0.05",IF(E12<0.1,"~ Marginal","✗ NS")))) | G12: Positive | H12: Airport earns +£38,825 vs Residential (reference)
A13: is_mall | B13: 26401.949 | C13: 6838.7691 | D13: =B13/C13 | E13: =2*(1-T.DIST(ABS(D13),306-10,TRUE)) | F13: =IF(E13<0.001,"★★★ p<0.001",IF(E13<0.01,"★★ p<0.01",IF(E13<0.05,"★ p<0.05",IF(E13<0.1,"~ Marginal","✗ NS")))) | G13: Positive | H13: Mall earns +£26,402 vs Residential (reference)
A15: Model-Level Statistics
A16: R-squared (R²) | B16: 0.8222 | D16: Proportion of variance in monthly_sales explained by the model
A17: Adjusted R² | B17: 0.8168 | D17: R² penalised for number of predictors
A18: Observations (n) | B18: 306 | D18: Clean rows after removing missing values
A19: No. of Predictors (k) | B19: 9 | D19: Excluding intercept
A20: Degrees of Freedom | B20: 296 | D20: n − k − 1
A21: SS Residual | B21: 5.7442869e+11 | D21: Sum of squared residuals (unexplained variance)
A22: SS Total | B22: 3.2312699e+12 | D22: Total sum of squares
A23: Variance Explained (%) | B23: 82.22% | D23: =R²×100
A25: Colour Key
A26: Green = Significant (p<0.05) | C26: Yellow = Marginal (p<0.10) | E26: Red/Plain = Not Significant (p≥0.10)

Sheet Predictions_Residuals
A1: Coefficient Reference Block (used by prediction formula) | K1: Coefficient Name | L1: Value
A2: store_id | B2: store_type | C2: region | D2: monthly_sales | E2: footfall | F2: marketing_spend | G2: inventory_availability_pct | H2: customer_rating | I2: avg_discount_pct | J2: holiday_flag | K2: is_high_street(IF) | L2: is_airport(IF) | M2: is_mall(IF) | N2: Predicted Sales | O2: Residual | P2: |Residual| | Q2: Rank | R2: Over/Under? | T2: Coeff Name | U2: Value
A3: STR-1001 | B3: Residential | C3: East | D3: 658832.62 | E3: 8302 | F3: 70389.11 | G3: 75 | H3: 3.1 | I3: 0.042 | J3: 1 | K3: =IF(B3="High Street",1,0) | L3: =IF(B3="Airport",1,0) | M3: =IF(B3="Mall",1,0) | N3: =$U$3+$U$4*E3+$U$5*F3+$U$6*G3+$U$7*H3+$U$8*I3+$U$9*J3+$U$10*K3+$U$11*L3+$U$12*M3 | O3: =D3-N3 | P3: =ABS(O3) | Q3: =RANK(P3,$P$3:$P$308,1) | R3: =IF(O3>0,"Over-predicted","Under-predicted") | T3: Intercept | U3: 73762.675
A4: STR-1001 | B4: Residential | C4: East | D4: 634436 | E4: 8487 | F4: 43827.89 | G4: 84.4 | H4: 2.8 | I4: 0.168 | J4: 0 | K4: =IF(B4="High Street",1,0) | L4: =IF(B4="Airport",1,0) | M4: =IF(B4="Mall",1,0) | N4: =$U$3+$U$4*E4+$U$5*F4+$U$6*G4+$U$7*H4+$U$8*I4+$U$9*J4+$U$10*K4+$U$11*L4+$U$12*M4 | O4: =D4-N4 | P4: =ABS(O4) | Q4: =RANK(P4,$P$3:$P$308,1) | R4: =IF(O4>0,"Over-predicted","Under-predicted") | T4: footfall | U4: 33.506639
A5: STR-1001 | B5: Residential | C5: East | D5: 678722.06 | E5: 9113 | F5: 59921.75 | G5: 88 | H5: 3.2 | I5: 0.133 | J5: 0 | K5: =IF(B5="High Street",1,0) | L5: =IF(B5="Airport",1,0) | M5: =IF(B5="Mall",1,0) | N5: =$U$3+$U$4*E5+$U$5*F5+$U$6*G5+$U$7*H5+$U$8*I5+$U$9*J5+$U$10*K5+$U$11*L5+$U$12*M5 | O5: =D5-N5 | P5: =ABS(O5) | Q5: =RANK(P5,$P$3:$P$308,1) | R5: =IF(O5>0,"Over-predicted","Under-predicted") | T5: marketing_spend | U5: 1.174046
A6: STR-1001 | B6: Residential | C6: East | D6: 658920.3 | E6: 9431 | F6: 56856.63 | G6: 86.9 | H6: 3.4 | I6: 0.142 | J6: 0 | K6: =IF(B6="High Street",1,0) | L6: =IF(B6="Airport",1,0) | M6: =IF(B6="Mall",1,0) | N6: =$U$3+$U$4*E6+$U$5*F6+$U$6*G6+$U$7*H6+$U$8*I6+$U$9*J6+$U$10*K6+$U$11*L6+$U$12*M6 | O6: =D6-N6 | P6: =ABS(O6) | Q6: =RANK(P6,$P$3:$P$308,1) | R6: =IF(O6>0,"Over-predicted","Under-predicted") | T6: inventory_availability_pct | U6: 2954.4359
A7: STR-1002 | B7: High Street | C7: East | D7: 741341.44 | E7: 9545 | F7: 48412.64 | G7: 97.6 | H7: 4.2 | I7: 0.231 | J7: 1 | K7: =IF(B7="High Street",1,0) | L7: =IF(B7="Airport",1,0) | M7: =IF(B7="Mall",1,0) | N7: =$U$3+$U$4*E7+$U$5*F7+$U$6*G7+$U$7*H7+$U$8*I7+$U$9*J7+$U$10*K7+$U$11*L7+$U$12*M7 | O7: =D7-N7 | P7: =ABS(O7) | Q7: =RANK(P7,$P$3:$P$308,1) | R7: =IF(O7>0,"Over-predicted","Under-predicted") | T7: customer_rating | U7: 12808.63
A8: STR-1002 | B8: High Street | C8: East | D8: 761835.34 | E8: 9792 | F8: 64811.21 | G8: 84.2 | H8: 4.2 | I8: 0.112 | J8: 0 | K8: =IF(B8="High Street",1,0) | L8: =IF(B8="Airport",1,0) | M8: =IF(B8="Mall",1,0) | N8: =$U$3+$U$4*E8+$U$5*F8+$U$6*G8+$U$7*H8+$U$8*I8+$U$9*J8+$U$10*K8+$U$11*L8+$U$12*M8 | O8: =D8-N8 | P8: =ABS(O8) | Q8: =RANK(P8,$P$3:$P$308,1) | R8: =IF(O8>0,"Over-predicted","Under-predicted") | T8: avg_discount_pct | U8: -57469.085
A9: STR-1002 | B9: High Street | C9: East | D9: 806615.54 | E9: 10616 | F9: 46213.45 | G9: 85.2 | H9: 4.1 | I9: 0.122 | J9: 1 | K9: =IF(B9="High Street",1,0) | L9: =IF(B9="Airport",1,0) | M9: =IF(B9="Mall",1,0) | N9: =$U$3+$U$4*E9+$U$5*F9+$U$6*G9+$U$7*H9+$U$8*I9+$U$9*J9+$U$10*K9+$U$11*L9+$U$12*M9 | O9: =D9-N9 | P9: =ABS(O9) | Q9: =RANK(P9,$P$3:$P$308,1) | R9: =IF(O9>0,"Over-predicted","Under-predicted") | T9: holiday_flag | U9: 11148.515
A10: STR-1002 | B10: High Street | C10: East | D10: 850164.26 | E10: 8567 | F10: 68148.52 | G10: 95.6 | H10: 3.9 | I10: 0.127 | J10: 0 | K10: =IF(B10="High Street",1,0) | L10: =IF(B10="Airport",1,0) | M10: =IF(B10="Mall",1,0) | N10: =$U$3+$U$4*E10+$U$5*F10+$U$6*G10+$U$7*H10+$U$8*I10+$U$9*J10+$U$10*K10+$U$11*L10+$U$12*M10 | O10: =D10-N10 | P10: =ABS(O10) | Q10: =RANK(P10,$P$3:$P$308,1) | R10: =IF(O10>0,"Over-predicted","Under-predicted") | T10: is_high_street | U10: 16295.025
A11: STR-1003 | B11: Airport | C11: North | D11: 930581.7 | E11: 10979 | F11: 71838.86 | G11: 88.6 | H11: 3.8 | I11: 0.215 | J11: 1 | K11: =IF(B11="High Street",1,0) | L11: =IF(B11="Airport",1,0) | M11: =IF(B11="Mall",1,0) | N11: =$U$3+$U$4*E11+$U$5*F11+$U$6*G11+$U$7*H11+$U$8*I11+$U$9*J11+$U$10*K11+$U$11*L11+$U$12*M11 | O11: =D11-N11 | P11: =ABS(O11) | Q11: =RANK(P11,$P$3:$P$308,1) | R11: =IF(O11>0,"Over-predicted","Under-predicted") | T11: is_airport | U11: 38824.963
A12: STR-1003 | B12: Airport | C12: North | D12: 779010.94 | E12: 9459 | F12: 68133.44 | G12: 85 | H12: 4.2 | I12: 0.22 | J12: 0 | K12: =IF(B12="High Street",1,0) | L12: =IF(B12="Airport",1,0) | M12: =IF(B12="Mall",1,0) | N12: =$U$3+$U$4*E12+$U$5*F12+$U$6*G12+$U$7*H12+$U$8*I12+$U$9*J12+$U$10*K12+$U$11*L12+$U$12*M12 | O12: =D12-N12 | P12: =ABS(O12) | Q12: =RANK(P12,$P$3:$P$308,1) | R12: =IF(O12>0,"Over-predicted","Under-predicted") | T12: is_mall | U12: 26401.949
A13: STR-1003 | B13: Airport | C13: North | D13: 723060.76 | E13: 9172 | F13: 34285.21 | G13: 88.3 | H13: 3.8 | I13: 0.213 | J13: 1 | K13: =IF(B13="High Street",1,0) | L13: =IF(B13="Airport",1,0) | M13: =IF(B13="Mall",1,0) | N13: =$U$3+$U$4*E13+$U$5*F13+$U$6*G13+$U$7*H13+$U$8*I13+$U$9*J13+$U$10*K13+$U$11*L13+$U$12*M13 | O13: =D13-N13 | P13: =ABS(O13) | Q13: =RANK(P13,$P$3:$P$308,1) | R13: =IF(O13>0,"Over-predicted","Under-predicted")
A14: STR-1003 | B14: Airport | C14: North | D14: 910791.94 | E14: 11230 | F14: 67979.88 | G14: 85.3 | H14: 3.8 | I14: 0.002 | J14: 0 | K14: =IF(B14="High Street",1,0) | L14: =IF(B14="Airport",1,0) | M14: =IF(B14="Mall",1,0) | N14: =$U$3+$U$4*E14+$U$5*F14+$U$6*G14+$U$7*H14+$U$8*I14+$U$9*J14+$U$10*K14+$U$11*L14+$U$12*M14 | O14: =D14-N14 | P14: =ABS(O14) | Q14: =RANK(P14,$P$3:$P$308,1) | R14: =IF(O14>0,"Over-predicted","Under-predicted")
A15: STR-1004 | B15: Residential | C15: East | D15: 922168.6 | E15: 12775 | F15: 71828.26 | G15: 81.7 | H15: 4.2 | I15: 0.116 | J15: 1 | K15: =IF(B15="High Street",1,0) | L15: =IF(B15="Airport",1,0) | M15: =IF(B15="Mall",1,0) | N15: =$U$3+$U$4*E15+$U$5*F15+$U$6*G15+$U$7*H15+$U$8*I15+$U$9*J15+$U$10*K15+$U$11*L15+$U$12*M15 | O15: =D15-N15 | P15: =ABS(O15) | Q15: =RANK(P15,$P$3:$P$308,1) | R15: =IF(O15>0,"Over-predicted","Under-predicted")
A16: STR-1004 | B16: Residential | C16: East | D16: 726606.28 | E16: 10054 | F16: 55716.82 | G16: 84.9 | H16: 4.3 | I16: 0.146 | J16: 0 | K16: =IF(B16="High Street",1,0) | L16: =IF(B16="Airport",1,0) | M16: =IF(B16="Mall",1,0) | N16: =$U$3+$U$4*E16+$U$5*F16+$U$6*G16+$U$7*H16+$U$8*I16+$U$9*J16+$U$10*K16+$U$11*L16+$U$12*M16 | O16: =D16-N16 | P16: =ABS(O16) | Q16: =RANK(P16,$P$3:$P$308,1) | R16: =IF(O16>0,"Over-predicted","Under-predicted")
A17: STR-1004 | B17: Residential | C17: East | D17: 746501.09 | E17: 8895 | F17: 59909.51 | G17: 88.8 | H17: 4.3 | I17: 0.228 | J17: 0 | K17: =IF(B17="High Street",1,0) | L17: =IF(B17="Airport",1,0) | M17: =IF(B17="Mall",1,0) | N17: =$U$3+$U$4*E17+$U$5*F17+$U$6*G17+$U$7*H17+$U$8*I17+$U$9*J17+$U$10*K17+$U$11*L17+$U$12*M17 | O17: =D17-N17 | P17: =ABS(O17) | Q17: =RANK(P17,$P$3:$P$308,1) | R17: =IF(O17>0,"Over-predicted","Under-predicted")
A18: STR-1004 | B18: Residential | C18: East | D18: 834017.02 | E18: 10940 | F18: 75305.71 | G18: 76.5 | H18: 4.5 | I18: 0.006 | J18: 0 | K18: =IF(B18="High Street",1,0) | L18: =IF(B18="Airport",1,0) | M18: =IF(B18="Mall",1,0) | N18: =$U$3+$U$4*E18+$U$5*F18+$U$6*G18+$U$7*H18+$U$8*I18+$U$9*J18+$U$10*K18+$U$11*L18+$U$12*M18 | O18: =D18-N18 | P18: =ABS(O18) | Q18: =RANK(P18,$P$3:$P$308,1) | R18: =IF(O18>0,"Over-predicted","Under-predicted")
A19: STR-1005 | B19: Residential | C19: South | D19: 666152.52 | E19: 7057 | F19: 48804.22 | G19: 87.7 | H19: 3.7 | I19: 0.005 | J19: 0 | K19: =IF(B19="High Street",1,0) | L19: =IF(B19="Airport",1,0) | M19: =IF(B19="Mall",1,0) | N19: =$U$3+$U$4*E19+$U$5*F19+$U$6*G19+$U$7*H19+$U$8*I19+$U$9*J19+$U$10*K19+$U$11*L19+$U$12*M19 | O19: =D19-N19 | P19: =ABS(O19) | Q19: =RANK(P19,$P$3:$P$308,1) | R19: =IF(O19>0,"Over-predicted","Under-predicted")
A20: STR-1005 | B20: Residential | C20: South | D20: 573155.19 | E20: 4263 | F20: 59117.9 | G20: 87.6 | H20: 3.6 | I20: 0.119 | J20: 0 | K20: =IF(B20="High Street",1,0) | L20: =IF(B20="Airport",1,0) | M20: =IF(B20="Mall",1,0) | N20: =$U$3+$U$4*E20+$U$5*F20+$U$6*G20+$U$7*H20+$U$8*I20+$U$9*J20+$U$10*K20+$U$11*L20+$U$12*M20 | O20: =D20-N20 | P20: =ABS(O20) | Q20: =RANK(P20,$P$3:$P$308,1) | R20: =IF(O20>0,"Over-predicted","Under-predicted")
A21: STR-1005 | B21: Residential | C21: South | D21: 666573.2 | E21: 5538 | F21: 78831.12 | G21: 94.1 | H21: 3.9 | I21: 0 | J21: 0 | K21: =IF(B21="High Street",1,0) | L21: =IF(B21="Airport",1,0) | M21: =IF(B21="Mall",1,0) | N21: =$U$3+$U$4*E21+$U$5*F21+$U$6*G21+$U$7*H21+$U$8*I21+$U$9*J21+$U$10*K21+$U$11*L21+$U$12*M21 | O21: =D21-N21 | P21: =ABS(O21) | Q21: =RANK(P21,$P$3:$P$308,1) | R21: =IF(O21>0,"Over-predicted","Under-predicted")
A22: STR-1005 | B22: Residential | C22: South | D22: 591619.95 | E22: 4865 | F22: 41441.93 | G22: 88.3 | H22: 4 | I22: 0.158 | J22: 0 | K22: =IF(B22="High Street",1,0) | L22: =IF(B22="Airport",1,0) | M22: =IF(B22="Mall",1,0) | N22: =$U$3+$U$4*E22+$U$5*F22+$U$6*G22+$U$7*H22+$U$8*I22+$U$9*J22+$U$10*K22+$U$11*L22+$U$12*M22 | O22: =D22-N22 | P22: =ABS(O22) | Q22: =RANK(P22,$P$3:$P$308,1) | R22: =IF(O22>0,"Over-predicted","Under-predicted")
A23: STR-1006 | B23: Residential | C23: North | D23: 415721.82 | E23: 2822 | F23: 30356.28 | G23: 84.8 | H23: 5 | I23: 0.231 | J23: 0 | K23: =IF(B23="High Street",1,0) | L23: =IF(B23="Airport",1,0) | M23: =IF(B23="Mall",1,0) | N23: =$U$3+$U$4*E23+$U$5*F23+$U$6*G23+$U$7*H23+$U$8*I23+$U$9*J23+$U$10*K23+$U$11*L23+$U$12*M23 | O23: =D23-N23 | P23: =ABS(O23) | Q23: =RANK(P23,$P$3:$P$308,1) | R23: =IF(O23>0,"Over-predicted","Under-predicted")
A24: STR-1006 | B24: Residential | C24: North | D24: 491905.13 | E24: 2121 | F24: 33518.88 | G24: 88.5 | H24: 5 | I24: 0.176 | J24: 0 | K24: =IF(B24="High Street",1,0) | L24: =IF(B24="Airport",1,0) | M24: =IF(B24="Mall",1,0) | N24: =$U$3+$U$4*E24+$U$5*F24+$U$6*G24+$U$7*H24+$U$8*I24+$U$9*J24+$U$10*K24+$U$11*L24+$U$12*M24 | O24: =D24-N24 | P24: =ABS(O24) | Q24: =RANK(P24,$P$3:$P$308,1) | R24: =IF(O24>0,"Over-predicted","Under-predicted")
... A308: STR-1080 | B308: Residential | C308: East | D308: 559660.84 | E308: 5317 | F308: 40553.11 | G308: 84.3 | H308: 4.1 | I308: 0.165 | J308: 0 | K308: =IF(B308="High Street",1,0) | L308: =IF(B308="Airport",1,0) | M308: =IF(B308="Mall",1,0) | N308: =$U$3+$U$4*E308+$U$5*F308+$U$6*G308+$U$7*H308+$U$8*I308+$U$9*J308+$U$10*K308+$U$11*L308+$U$12*M308 | O308: =D308-N308 | P308: =ABS(O308) | Q308: =RANK(P308,$P$3:$P$308,1) | R308: =IF(O308>0,"Over-predicted","Under-predicted")
A311: Residual Summary Statistics (Excel formulas)
A312: Metric | B312: Formula Result | C312: Interpretation
A313: Mean of Residuals | B313: =AVERAGE(O3:O308) | C313: Should be ≈ 0 for a valid OLS model
A314: Mean |Residual| | B314: =AVERAGE(P3:P308) | C314: Average absolute prediction error
A315: Max Positive Residual | B315: =MAX(O3:O308) | C315: Largest outperformer
A316: Max Negative Residual | B316: =MIN(O3:O308) | C316: Largest underperformer
A317: RMSE (Root Mean Sq Error) | B317: =SQRT(SUMPRODUCT(O3:O308,O3:O308)/(306-10)) | C317: Model standard error

Sheet Model_Comparison
A1: Model Comparison — All Regression Models
A2: Criteria | B2: Model 1 — Footfall (Simple) | C2: Model 2 — Marketing Spend (Simple) | D2: Model 3 — Multiple Regression (FINAL ✓)
A3: Model Type | B3: Simple Linear Regression | C3: Simple Linear Regression | D3: Multiple Linear Regression
A4: Dependent Variable | B4: monthly_sales | C4: monthly_sales | D4: monthly_sales
A5: No. of Predictors | B5: =1 | C5: =1 | D5: =9
A6: Independent Variables | B6: footfall | C6: marketing_spend | D6: footfall, marketing_spend, inventory_availability_pct, customer_rating, avg_discount_pct, holiday_flag, is_high_street, is_airport, is_mall
A7: Includes Dummy Variables? | B7: No | C7: No | D7: Yes — is_high_street, is_airport, is_mall (ref: Residential)
A8: R-squared | B8: =INDEX(LINEST(Cleaned_Data!$M$3:$M$308,Cleaned_Data!$F$3:$F$308,TRUE,TRUE),3,1) | C8: =INDEX(LINEST(Cleaned_Data!$M$3:$M$308,Cleaned_Data!$E$3:$E$308,TRUE,TRUE),3,1) | D8: 0.8222
A9: R-squared % | B9: =TEXT(INDEX(LINEST(Cleaned_Data!$M$3:$M$308,Cleaned_Data!$F$3:$F$308,TRUE,TRUE),3,1)*100,"0.00")&"%" | C9: =TEXT(INDEX(LINEST(Cleaned_Data!$M$3:$M$308,Cleaned_Data!$E$3:$E$308,TRUE,TRUE),3,1)*100,"0.00")&"%" | D9: =TEXT(0.8222*100,"0.00")&"%"
A10: Adjusted R-squared | B10: N/A (1 predictor) | C10: N/A (1 predictor) | D10: 0.8168
A11: Intercept (£) | B11: 447699.03 | C11: 567463.56 | D11: 73762.67
A12: Key Predictor Coefficient | B12: footfall = 35.6415 | C12: marketing_spend = 2.051932 | D12: footfall = 33.5066, mktg = 1.174, inventory = 2954.44
A13: Significant Variables (p<0.05) | B13: footfall (p<0.001) | C13: marketing_spend (p<0.001) | D13: footfall, marketing_spend, inventory_availability_pct, customer_rating, is_high_street, is_airport, is_mall
A14: Non-Significant Variables | B14: None | C14: None | D14: avg_discount_pct (p=0.125), holiday_flag (p=0.098)
A15: Business Usefulness | B15: High — footfall strategy | C15: Moderate — marketing ROI baseline | D15: HIGHEST — covers all business levers
A16: Key Limitation | B16: Ignores all other levers | C16: Explains only 15.7% of variance | D16: Assumes linearity; 4 months only
A17: Is Final Model? | B17: No | C17: No | D17: YES ✓
